INFO:itchat:Getting uuid of QR code.
INFO:itchat:Downloading QR code.
INFO:itchat:Please scan the QR code to log in.
INFO:itchat:Getting uuid of QR code.
INFO:itchat:Downloading QR code.
INFO:itchat:Please scan the QR code to log in.
INFO:itchat:Please press confirm on your phone.
INFO:itchat:Loading the contact, this may take a little while.
Caroline__PYQuanPin:Caroline
小威__PYQuanPin:xiaowei
阡陌🍃__PYQuanPin:qianmospanclassemojiemoji1f343span
张大帅__PYQuanPin:zhangdashuai
左涛瑞__PYQuanPin:zuotaorui
💯哈哈吴君志__PYQuanPin:?hahawujunzhi
吕春阳__PYQuanPin:lvchunyang
初见__PYQuanPin:chujian
奥普乐欢乐水世界__PYQuanPin:aopuyuehuanyueshuishijie
小胖__PYQuanPin:xiaopan
张创科老师13679260573__PYQuanPin:zhangchuangkelaoshi13679260573
人生在于拼搏__PYQuanPin:renshengzaiyupinbo
戴维__PYQuanPin:daiwei
Kerwin.徐__PYQuanPin:Kerwinxu
SUNNY__PYQuanPin:SUNNY
long__PYQuanPin:long
ONLY.love__PYQuanPin:ONLYlove
木子__PYQuanPin:muzi
Wong__PYQuanPin:Wong
携手声光舞美志远13080163331__PYQuanPin:xieshoushengguangwumeizhiyuan13080163331
乔布熙__PYQuanPin:qiaobuxi
fun__PYQuanPin:fun
A There won'r be you__PYQuanPin:ATherewonrbeyou
Mr.黑咖啡__PYQuanPin:Mrheigafei
哇塞天哪__PYQuanPin:wasaitianna
月亮__PYQuanPin:yueliang
你男朋友叫文杰么❇__PYQuanPin:ninanpengyoujiaowenjiemespanclassemojiemoji2747span
沛沛__PYQuanPin:peipei
路由__PYQuanPin:luyou
洋洋专业音响舞美__PYQuanPin:yangyangzhuanyeyinxiangwumei
影子传说__PYQuanPin:yingzichuanshui
无知__PYQuanPin:wuzhi
颖颖WANG__PYQuanPin:yingyingWANG
A.瀚雄金融服务__PYQuanPin:Ahanxiongjinrongfuwu
Panna__PYQuanPin:Panna
素颜最美__PYQuanPin:suyanzuimei
弓长__PYQuanPin:gongchang
小宇__PYQuanPin:xiaoyu
其实、等风来__PYQuanPin:qishidengfenglai
天之骄子__PYQuanPin:tianzhijiaozi
大海__PYQuanPin:dahai
爱吖、__PYQuanPin:aia
Adolph__PYQuanPin:Adolph
文林__PYQuanPin:wenlin
飞侠__PYQuanPin:feixia
马军胜__PYQuanPin:majunsheng
努比亚许昌解亚青__PYQuanPin:nubiyaxuchangxieyaqing
刘敏__PYQuanPin:liumin
功不唐捐__PYQuanPin:gongbutangjuan
知足常乐！红军__PYQuanPin:zhizuchangyuehongjun
云端漫步__PYQuanPin:yunduanmanbu
张勋__PYQuanPin:zhangxun
你好，亲爱的__PYQuanPin:nihaoqinaide
y帅__PYQuanPin:yshuai
吕阳阳__PYQuanPin:lvyangyang
Still me 。。。__PYQuanPin:Stillme
214℃™love__PYQuanPin:214spanclassemojiemoji2122spanlove
李凯龙__PYQuanPin:likailong
llj__PYQuanPin:llj
奔跑的小蜗牛__PYQuanPin:benpaodexiaowoniu
擱淺的往事__PYQuanPin:gejiandewangshi
陌陌__PYQuanPin:momo
郝廉龙__PYQuanPin:haolianlong
暗里着迷（郭洋15527277905）__PYQuanPin:anlizhaomiguoyang15527277905
老曹__PYQuanPin:laocao
洋洋__PYQuanPin:yangyang
POWER__PYQuanPin:POWER
啦啦啦__PYQuanPin:lalala
随心而遇__PYQuanPin:suixineryu
仰望星空(*^ω^*)__PYQuanPin:yangwangxingkong
旧时光__PYQuanPin:jiushiguang
依栘__PYQuanPin:yiyi
Holo__PYQuanPin:Holo
春辉__PYQuanPin:chunhui
A 李艳清__PYQuanPin:Aliyanqing
小杰__PYQuanPin:xiaojie
张玉魁18637417318__PYQuanPin:zhangyukui18637417318
强__PYQuanPin:qiang
十木__PYQuanPin:shimu
闫帅峰__PYQuanPin:yanshuaifeng
张培歌__PYQuanPin:zhangpeige
黄晓俊__PYQuanPin:huangxiaojun
马光__PYQuanPin:maguang
靳子帅__PYQuanPin:jinzishuai
杨高星__PYQuanPin:yanggaoxing
皮皮鲁__PYQuanPin:pipilu
黄果果爱的草莓派__PYQuanPin:huangguoguoaidecaomeipa
讯联☁️-Vivian__PYQuanPin:xunlianspanclassemojiemoji2601span?Vivian
浪花店小二__PYQuanPin:langhuadianxiaoer
张艺__PYQuanPin:zhangyi
淡墨__PYQuanPin:danmo
杨利卡17739777285__PYQuanPin:yanglika17739777285
我非英雄__PYQuanPin:wofeiyingxiong
张占胜__PYQuanPin:zhangzhansheng
青云__PYQuanPin:qingyun
༒Leon༒__PYQuanPin:?Leon?
殷清__PYQuanPin:yinqing
庄Sir__PYQuanPin:zhuangSir
闯先生__PYQuanPin:chuangxiansheng
小解__PYQuanPin:xiaoxie
莉莉__PYQuanPin:lili
演👮 员__PYQuanPin:yanspanclassemojiemoji1f46espanyuan
柯森__PYQuanPin:kesen
樊小铭🙃__PYQuanPin:fanxiaoming?
孙同学__PYQuanPin:suntongxue
INFO:itchat:Start auto replying.
ERROR:itchat:Traceback (most recent call last):
  File "C:\Python36\lib\site-packages\urllib3\connection.py", line 141, in _new_conn
    (self.host, self.port), self.timeout, **extra_kw)
  File "C:\Python36\lib\site-packages\urllib3\util\connection.py", line 60, in create_connection
    for res in socket.getaddrinfo(host, port, family, socket.SOCK_STREAM):
  File "C:\Python36\lib\socket.py", line 743, in getaddrinfo
    for res in _socket.getaddrinfo(host, port, family, type, proto, flags):
socket.gaierror: [Errno 11004] getaddrinfo failed

During handling of the above exception, another exception occurred:

Traceback (most recent call last):
  File "C:\Python36\lib\site-packages\urllib3\connectionpool.py", line 600, in urlopen
    chunked=chunked)
  File "C:\Python36\lib\site-packages\urllib3\connectionpool.py", line 345, in _make_request
    self._validate_conn(conn)
  File "C:\Python36\lib\site-packages\urllib3\connectionpool.py", line 844, in _validate_conn
    conn.connect()
  File "C:\Python36\lib\site-packages\urllib3\connection.py", line 284, in connect
    conn = self._new_conn()
  File "C:\Python36\lib\site-packages\urllib3\connection.py", line 150, in _new_conn
    self, "Failed to establish a new connection: %s" % e)
urllib3.exceptions.NewConnectionError: <urllib3.connection.VerifiedHTTPSConnection object at 0x02FC09F0>: Failed to establish a new connection: [Errno 11004] getaddrinfo failed

During handling of the above exception, another exception occurred:

Traceback (most recent call last):
  File "C:\Python36\lib\site-packages\requests\adapters.py", line 440, in send
    timeout=timeout
  File "C:\Python36\lib\site-packages\urllib3\connectionpool.py", line 649, in urlopen
    _stacktrace=sys.exc_info()[2])
  File "C:\Python36\lib\site-packages\urllib3\util\retry.py", line 388, in increment
    raise MaxRetryError(_pool, url, error or ResponseError(cause))
urllib3.exceptions.MaxRetryError: HTTPSConnectionPool(host='webpush.wx.qq.com', port=443): Max retries exceeded with url: /cgi-bin/mmwebwx-bin/synccheck?r=1499223216295&skey=%40crypt_1ad16c4_05d572229b40420fbbb1a28d4e90d16b&sid=utWLW%2BzfoVBfEKmS&uin=470536655&deviceid=e429345087967561&synckey=1_673300149%7C2_673300242%7C3_673300210%7C11_673300077%7C13_673270493%7C201_1499223159%7C1000_1499215980%7C1001_1499216252&_=1499223216295 (Caused by NewConnectionError('<urllib3.connection.VerifiedHTTPSConnection object at 0x02FC09F0>: Failed to establish a new connection: [Errno 11004] getaddrinfo failed',))

During handling of the above exception, another exception occurred:

Traceback (most recent call last):
  File "C:\Python36\lib\site-packages\itchat\components\login.py", line 240, in maintain_loop
    i = sync_check(self)
  File "C:\Python36\lib\site-packages\itchat\components\login.py", line 295, in sync_check
    r = self.s.get(url, params=params, headers=headers, timeout=config.TIMEOUT)
  File "C:\Python36\lib\site-packages\requests\sessions.py", line 515, in get
    return self.request('GET', url, **kwargs)
  File "C:\Python36\lib\site-packages\requests\sessions.py", line 502, in request
    resp = self.send(prep, **send_kwargs)
  File "C:\Python36\lib\site-packages\requests\sessions.py", line 612, in send
    r = adapter.send(request, **kwargs)
  File "C:\Python36\lib\site-packages\requests\adapters.py", line 504, in send
    raise ConnectionError(e, request=request)
requests.exceptions.ConnectionError: HTTPSConnectionPool(host='webpush.wx.qq.com', port=443): Max retries exceeded with url: /cgi-bin/mmwebwx-bin/synccheck?r=1499223216295&skey=%40crypt_1ad16c4_05d572229b40420fbbb1a28d4e90d16b&sid=utWLW%2BzfoVBfEKmS&uin=470536655&deviceid=e429345087967561&synckey=1_673300149%7C2_673300242%7C3_673300210%7C11_673300077%7C13_673270493%7C201_1499223159%7C1000_1499215980%7C1001_1499216252&_=1499223216295 (Caused by NewConnectionError('<urllib3.connection.VerifiedHTTPSConnection object at 0x02FC09F0>: Failed to establish a new connection: [Errno 11004] getaddrinfo failed',))

ERROR:itchat:Traceback (most recent call last):
  File "C:\Python36\lib\site-packages\urllib3\connection.py", line 141, in _new_conn
    (self.host, self.port), self.timeout, **extra_kw)
  File "C:\Python36\lib\site-packages\urllib3\util\connection.py", line 60, in create_connection
    for res in socket.getaddrinfo(host, port, family, socket.SOCK_STREAM):
  File "C:\Python36\lib\socket.py", line 743, in getaddrinfo
    for res in _socket.getaddrinfo(host, port, family, type, proto, flags):
socket.gaierror: [Errno 11004] getaddrinfo failed

During handling of the above exception, another exception occurred:

Traceback (most recent call last):
  File "C:\Python36\lib\site-packages\urllib3\connectionpool.py", line 600, in urlopen
    chunked=chunked)
  File "C:\Python36\lib\site-packages\urllib3\connectionpool.py", line 345, in _make_request
    self._validate_conn(conn)
  File "C:\Python36\lib\site-packages\urllib3\connectionpool.py", line 844, in _validate_conn
    conn.connect()
  File "C:\Python36\lib\site-packages\urllib3\connection.py", line 284, in connect
    conn = self._new_conn()
  File "C:\Python36\lib\site-packages\urllib3\connection.py", line 150, in _new_conn
    self, "Failed to establish a new connection: %s" % e)
urllib3.exceptions.NewConnectionError: <urllib3.connection.VerifiedHTTPSConnection object at 0x02FF2370>: Failed to establish a new connection: [Errno 11004] getaddrinfo failed

During handling of the above exception, another exception occurred:

Traceback (most recent call last):
  File "C:\Python36\lib\site-packages\requests\adapters.py", line 440, in send
    timeout=timeout
  File "C:\Python36\lib\site-packages\urllib3\connectionpool.py", line 649, in urlopen
    _stacktrace=sys.exc_info()[2])
  File "C:\Python36\lib\site-packages\urllib3\util\retry.py", line 388, in increment
    raise MaxRetryError(_pool, url, error or ResponseError(cause))
urllib3.exceptions.MaxRetryError: HTTPSConnectionPool(host='webpush.wx.qq.com', port=443): Max retries exceeded with url: /cgi-bin/mmwebwx-bin/synccheck?r=1499223229301&skey=%40crypt_1ad16c4_05d572229b40420fbbb1a28d4e90d16b&sid=utWLW%2BzfoVBfEKmS&uin=470536655&deviceid=e429345087967561&synckey=1_673300149%7C2_673300242%7C3_673300210%7C11_673300077%7C13_673270493%7C201_1499223159%7C1000_1499215980%7C1001_1499216252&_=1499223229301 (Caused by NewConnectionError('<urllib3.connection.VerifiedHTTPSConnection object at 0x02FF2370>: Failed to establish a new connection: [Errno 11004] getaddrinfo failed',))

During handling of the above exception, another exception occurred:

Traceback (most recent call last):
  File "C:\Python36\lib\site-packages\itchat\components\login.py", line 240, in maintain_loop
    i = sync_check(self)
  File "C:\Python36\lib\site-packages\itchat\components\login.py", line 295, in sync_check
    r = self.s.get(url, params=params, headers=headers, timeout=config.TIMEOUT)
  File "C:\Python36\lib\site-packages\requests\sessions.py", line 515, in get
    return self.request('GET', url, **kwargs)
  File "C:\Python36\lib\site-packages\requests\sessions.py", line 502, in request
    resp = self.send(prep, **send_kwargs)
  File "C:\Python36\lib\site-packages\requests\sessions.py", line 612, in send
    r = adapter.send(request, **kwargs)
  File "C:\Python36\lib\site-packages\requests\adapters.py", line 504, in send
    raise ConnectionError(e, request=request)
requests.exceptions.ConnectionError: HTTPSConnectionPool(host='webpush.wx.qq.com', port=443): Max retries exceeded with url: /cgi-bin/mmwebwx-bin/synccheck?r=1499223229301&skey=%40crypt_1ad16c4_05d572229b40420fbbb1a28d4e90d16b&sid=utWLW%2BzfoVBfEKmS&uin=470536655&deviceid=e429345087967561&synckey=1_673300149%7C2_673300242%7C3_673300210%7C11_673300077%7C13_673270493%7C201_1499223159%7C1000_1499215980%7C1001_1499216252&_=1499223229301 (Caused by NewConnectionError('<urllib3.connection.VerifiedHTTPSConnection object at 0x02FF2370>: Failed to establish a new connection: [Errno 11004] getaddrinfo failed',))

ERROR:itchat:Traceback (most recent call last):
  File "C:\Python36\lib\site-packages\urllib3\connection.py", line 141, in _new_conn
    (self.host, self.port), self.timeout, **extra_kw)
  File "C:\Python36\lib\site-packages\urllib3\util\connection.py", line 60, in create_connection
    for res in socket.getaddrinfo(host, port, family, socket.SOCK_STREAM):
  File "C:\Python36\lib\socket.py", line 743, in getaddrinfo
    for res in _socket.getaddrinfo(host, port, family, type, proto, flags):
socket.gaierror: [Errno 11004] getaddrinfo failed

During handling of the above exception, another exception occurred:

Traceback (most recent call last):
  File "C:\Python36\lib\site-packages\urllib3\connectionpool.py", line 600, in urlopen
    chunked=chunked)
  File "C:\Python36\lib\site-packages\urllib3\connectionpool.py", line 345, in _make_request
    self._validate_conn(conn)
  File "C:\Python36\lib\site-packages\urllib3\connectionpool.py", line 844, in _validate_conn
    conn.connect()
  File "C:\Python36\lib\site-packages\urllib3\connection.py", line 284, in connect
    conn = self._new_conn()
  File "C:\Python36\lib\site-packages\urllib3\connection.py", line 150, in _new_conn
    self, "Failed to establish a new connection: %s" % e)
urllib3.exceptions.NewConnectionError: <urllib3.connection.VerifiedHTTPSConnection object at 0x02FF28D0>: Failed to establish a new connection: [Errno 11004] getaddrinfo failed

During handling of the above exception, another exception occurred:

Traceback (most recent call last):
  File "C:\Python36\lib\site-packages\requests\adapters.py", line 440, in send
    timeout=timeout
  File "C:\Python36\lib\site-packages\urllib3\connectionpool.py", line 649, in urlopen
    _stacktrace=sys.exc_info()[2])
  File "C:\Python36\lib\site-packages\urllib3\util\retry.py", line 388, in increment
    raise MaxRetryError(_pool, url, error or ResponseError(cause))
urllib3.exceptions.MaxRetryError: HTTPSConnectionPool(host='webpush.wx.qq.com', port=443): Max retries exceeded with url: /cgi-bin/mmwebwx-bin/synccheck?r=1499223242305&skey=%40crypt_1ad16c4_05d572229b40420fbbb1a28d4e90d16b&sid=utWLW%2BzfoVBfEKmS&uin=470536655&deviceid=e429345087967561&synckey=1_673300149%7C2_673300242%7C3_673300210%7C11_673300077%7C13_673270493%7C201_1499223159%7C1000_1499215980%7C1001_1499216252&_=1499223242305 (Caused by NewConnectionError('<urllib3.connection.VerifiedHTTPSConnection object at 0x02FF28D0>: Failed to establish a new connection: [Errno 11004] getaddrinfo failed',))

During handling of the above exception, another exception occurred:

Traceback (most recent call last):
  File "C:\Python36\lib\site-packages\itchat\components\login.py", line 240, in maintain_loop
    i = sync_check(self)
  File "C:\Python36\lib\site-packages\itchat\components\login.py", line 295, in sync_check
    r = self.s.get(url, params=params, headers=headers, timeout=config.TIMEOUT)
  File "C:\Python36\lib\site-packages\requests\sessions.py", line 515, in get
    return self.request('GET', url, **kwargs)
  File "C:\Python36\lib\site-packages\requests\sessions.py", line 502, in request
    resp = self.send(prep, **send_kwargs)
  File "C:\Python36\lib\site-packages\requests\sessions.py", line 612, in send
    r = adapter.send(request, **kwargs)
  File "C:\Python36\lib\site-packages\requests\adapters.py", line 504, in send
    raise ConnectionError(e, request=request)
requests.exceptions.ConnectionError: HTTPSConnectionPool(host='webpush.wx.qq.com', port=443): Max retries exceeded with url: /cgi-bin/mmwebwx-bin/synccheck?r=1499223242305&skey=%40crypt_1ad16c4_05d572229b40420fbbb1a28d4e90d16b&sid=utWLW%2BzfoVBfEKmS&uin=470536655&deviceid=e429345087967561&synckey=1_673300149%7C2_673300242%7C3_673300210%7C11_673300077%7C13_673270493%7C201_1499223159%7C1000_1499215980%7C1001_1499216252&_=1499223242305 (Caused by NewConnectionError('<urllib3.connection.VerifiedHTTPSConnection object at 0x02FF28D0>: Failed to establish a new connection: [Errno 11004] getaddrinfo failed',))

ERROR:itchat:Traceback (most recent call last):
  File "C:\Python36\lib\site-packages\urllib3\connection.py", line 141, in _new_conn
    (self.host, self.port), self.timeout, **extra_kw)
  File "C:\Python36\lib\site-packages\urllib3\util\connection.py", line 60, in create_connection
    for res in socket.getaddrinfo(host, port, family, socket.SOCK_STREAM):
  File "C:\Python36\lib\socket.py", line 743, in getaddrinfo
    for res in _socket.getaddrinfo(host, port, family, type, proto, flags):
socket.gaierror: [Errno 11004] getaddrinfo failed

During handling of the above exception, another exception occurred:

Traceback (most recent call last):
  File "C:\Python36\lib\site-packages\urllib3\connectionpool.py", line 600, in urlopen
    chunked=chunked)
  File "C:\Python36\lib\site-packages\urllib3\connectionpool.py", line 345, in _make_request
    self._validate_conn(conn)
  File "C:\Python36\lib\site-packages\urllib3\connectionpool.py", line 844, in _validate_conn
    conn.connect()
  File "C:\Python36\lib\site-packages\urllib3\connection.py", line 284, in connect
    conn = self._new_conn()
  File "C:\Python36\lib\site-packages\urllib3\connection.py", line 150, in _new_conn
    self, "Failed to establish a new connection: %s" % e)
urllib3.exceptions.NewConnectionError: <urllib3.connection.VerifiedHTTPSConnection object at 0x02FF2D70>: Failed to establish a new connection: [Errno 11004] getaddrinfo failed

During handling of the above exception, another exception occurred:

Traceback (most recent call last):
  File "C:\Python36\lib\site-packages\requests\adapters.py", line 440, in send
    timeout=timeout
  File "C:\Python36\lib\site-packages\urllib3\connectionpool.py", line 649, in urlopen
    _stacktrace=sys.exc_info()[2])
  File "C:\Python36\lib\site-packages\urllib3\util\retry.py", line 388, in increment
    raise MaxRetryError(_pool, url, error or ResponseError(cause))
urllib3.exceptions.MaxRetryError: HTTPSConnectionPool(host='webpush.wx.qq.com', port=443): Max retries exceeded with url: /cgi-bin/mmwebwx-bin/synccheck?r=1499223255309&skey=%40crypt_1ad16c4_05d572229b40420fbbb1a28d4e90d16b&sid=utWLW%2BzfoVBfEKmS&uin=470536655&deviceid=e429345087967561&synckey=1_673300149%7C2_673300242%7C3_673300210%7C11_673300077%7C13_673270493%7C201_1499223159%7C1000_1499215980%7C1001_1499216252&_=1499223255309 (Caused by NewConnectionError('<urllib3.connection.VerifiedHTTPSConnection object at 0x02FF2D70>: Failed to establish a new connection: [Errno 11004] getaddrinfo failed',))

During handling of the above exception, another exception occurred:

Traceback (most recent call last):
  File "C:\Python36\lib\site-packages\itchat\components\login.py", line 240, in maintain_loop
    i = sync_check(self)
  File "C:\Python36\lib\site-packages\itchat\components\login.py", line 295, in sync_check
    r = self.s.get(url, params=params, headers=headers, timeout=config.TIMEOUT)
  File "C:\Python36\lib\site-packages\requests\sessions.py", line 515, in get
    return self.request('GET', url, **kwargs)
  File "C:\Python36\lib\site-packages\requests\sessions.py", line 502, in request
    resp = self.send(prep, **send_kwargs)
  File "C:\Python36\lib\site-packages\requests\sessions.py", line 612, in send
    r = adapter.send(request, **kwargs)
  File "C:\Python36\lib\site-packages\requests\adapters.py", line 504, in send
    raise ConnectionError(e, request=request)
requests.exceptions.ConnectionError: HTTPSConnectionPool(host='webpush.wx.qq.com', port=443): Max retries exceeded with url: /cgi-bin/mmwebwx-bin/synccheck?r=1499223255309&skey=%40crypt_1ad16c4_05d572229b40420fbbb1a28d4e90d16b&sid=utWLW%2BzfoVBfEKmS&uin=470536655&deviceid=e429345087967561&synckey=1_673300149%7C2_673300242%7C3_673300210%7C11_673300077%7C13_673270493%7C201_1499223159%7C1000_1499215980%7C1001_1499216252&_=1499223255309 (Caused by NewConnectionError('<urllib3.connection.VerifiedHTTPSConnection object at 0x02FF2D70>: Failed to establish a new connection: [Errno 11004] getaddrinfo failed',))

ERROR:itchat:Traceback (most recent call last):
  File "C:\Python36\lib\site-packages\urllib3\connection.py", line 141, in _new_conn
    (self.host, self.port), self.timeout, **extra_kw)
  File "C:\Python36\lib\site-packages\urllib3\util\connection.py", line 60, in create_connection
    for res in socket.getaddrinfo(host, port, family, socket.SOCK_STREAM):
  File "C:\Python36\lib\socket.py", line 743, in getaddrinfo
    for res in _socket.getaddrinfo(host, port, family, type, proto, flags):
socket.gaierror: [Errno 11004] getaddrinfo failed

During handling of the above exception, another exception occurred:

Traceback (most recent call last):
  File "C:\Python36\lib\site-packages\urllib3\connectionpool.py", line 600, in urlopen
    chunked=chunked)
  File "C:\Python36\lib\site-packages\urllib3\connectionpool.py", line 345, in _make_request
    self._validate_conn(conn)
  File "C:\Python36\lib\site-packages\urllib3\connectionpool.py", line 844, in _validate_conn
    conn.connect()
  File "C:\Python36\lib\site-packages\urllib3\connection.py", line 284, in connect
    conn = self._new_conn()
  File "C:\Python36\lib\site-packages\urllib3\connection.py", line 150, in _new_conn
    self, "Failed to establish a new connection: %s" % e)
urllib3.exceptions.NewConnectionError: <urllib3.connection.VerifiedHTTPSConnection object at 0x02FF2F70>: Failed to establish a new connection: [Errno 11004] getaddrinfo failed

During handling of the above exception, another exception occurred:

Traceback (most recent call last):
  File "C:\Python36\lib\site-packages\requests\adapters.py", line 440, in send
    timeout=timeout
  File "C:\Python36\lib\site-packages\urllib3\connectionpool.py", line 649, in urlopen
    _stacktrace=sys.exc_info()[2])
  File "C:\Python36\lib\site-packages\urllib3\util\retry.py", line 388, in increment
    raise MaxRetryError(_pool, url, error or ResponseError(cause))
urllib3.exceptions.MaxRetryError: HTTPSConnectionPool(host='webpush.wx.qq.com', port=443): Max retries exceeded with url: /cgi-bin/mmwebwx-bin/synccheck?r=1499223268313&skey=%40crypt_1ad16c4_05d572229b40420fbbb1a28d4e90d16b&sid=utWLW%2BzfoVBfEKmS&uin=470536655&deviceid=e429345087967561&synckey=1_673300149%7C2_673300242%7C3_673300210%7C11_673300077%7C13_673270493%7C201_1499223159%7C1000_1499215980%7C1001_1499216252&_=1499223268313 (Caused by NewConnectionError('<urllib3.connection.VerifiedHTTPSConnection object at 0x02FF2F70>: Failed to establish a new connection: [Errno 11004] getaddrinfo failed',))

During handling of the above exception, another exception occurred:

Traceback (most recent call last):
  File "C:\Python36\lib\site-packages\itchat\components\login.py", line 240, in maintain_loop
    i = sync_check(self)
  File "C:\Python36\lib\site-packages\itchat\components\login.py", line 295, in sync_check
    r = self.s.get(url, params=params, headers=headers, timeout=config.TIMEOUT)
  File "C:\Python36\lib\site-packages\requests\sessions.py", line 515, in get
    return self.request('GET', url, **kwargs)
  File "C:\Python36\lib\site-packages\requests\sessions.py", line 502, in request
    resp = self.send(prep, **send_kwargs)
  File "C:\Python36\lib\site-packages\requests\sessions.py", line 612, in send
    r = adapter.send(request, **kwargs)
  File "C:\Python36\lib\site-packages\requests\adapters.py", line 504, in send
    raise ConnectionError(e, request=request)
requests.exceptions.ConnectionError: HTTPSConnectionPool(host='webpush.wx.qq.com', port=443): Max retries exceeded with url: /cgi-bin/mmwebwx-bin/synccheck?r=1499223268313&skey=%40crypt_1ad16c4_05d572229b40420fbbb1a28d4e90d16b&sid=utWLW%2BzfoVBfEKmS&uin=470536655&deviceid=e429345087967561&synckey=1_673300149%7C2_673300242%7C3_673300210%7C11_673300077%7C13_673270493%7C201_1499223159%7C1000_1499215980%7C1001_1499216252&_=1499223268313 (Caused by NewConnectionError('<urllib3.connection.VerifiedHTTPSConnection object at 0x02FF2F70>: Failed to establish a new connection: [Errno 11004] getaddrinfo failed',))

ERROR:itchat:Traceback (most recent call last):
  File "C:\Python36\lib\site-packages\urllib3\connection.py", line 141, in _new_conn
    (self.host, self.port), self.timeout, **extra_kw)
  File "C:\Python36\lib\site-packages\urllib3\util\connection.py", line 60, in create_connection
    for res in socket.getaddrinfo(host, port, family, socket.SOCK_STREAM):
  File "C:\Python36\lib\socket.py", line 743, in getaddrinfo
    for res in _socket.getaddrinfo(host, port, family, type, proto, flags):
socket.gaierror: [Errno 11004] getaddrinfo failed

During handling of the above exception, another exception occurred:

Traceback (most recent call last):
  File "C:\Python36\lib\site-packages\urllib3\connectionpool.py", line 600, in urlopen
    chunked=chunked)
  File "C:\Python36\lib\site-packages\urllib3\connectionpool.py", line 345, in _make_request
    self._validate_conn(conn)
  File "C:\Python36\lib\site-packages\urllib3\connectionpool.py", line 844, in _validate_conn
    conn.connect()
  File "C:\Python36\lib\site-packages\urllib3\connection.py", line 284, in connect
    conn = self._new_conn()
  File "C:\Python36\lib\site-packages\urllib3\connection.py", line 150, in _new_conn
    self, "Failed to establish a new connection: %s" % e)
urllib3.exceptions.NewConnectionError: <urllib3.connection.VerifiedHTTPSConnection object at 0x02FF2770>: Failed to establish a new connection: [Errno 11004] getaddrinfo failed

During handling of the above exception, another exception occurred:

Traceback (most recent call last):
  File "C:\Python36\lib\site-packages\requests\adapters.py", line 440, in send
    timeout=timeout
  File "C:\Python36\lib\site-packages\urllib3\connectionpool.py", line 649, in urlopen
    _stacktrace=sys.exc_info()[2])
  File "C:\Python36\lib\site-packages\urllib3\util\retry.py", line 388, in increment
    raise MaxRetryError(_pool, url, error or ResponseError(cause))
urllib3.exceptions.MaxRetryError: HTTPSConnectionPool(host='webpush.wx.qq.com', port=443): Max retries exceeded with url: /cgi-bin/mmwebwx-bin/synccheck?r=1499223281317&skey=%40crypt_1ad16c4_05d572229b40420fbbb1a28d4e90d16b&sid=utWLW%2BzfoVBfEKmS&uin=470536655&deviceid=e429345087967561&synckey=1_673300149%7C2_673300242%7C3_673300210%7C11_673300077%7C13_673270493%7C201_1499223159%7C1000_1499215980%7C1001_1499216252&_=1499223281317 (Caused by NewConnectionError('<urllib3.connection.VerifiedHTTPSConnection object at 0x02FF2770>: Failed to establish a new connection: [Errno 11004] getaddrinfo failed',))

During handling of the above exception, another exception occurred:

Traceback (most recent call last):
  File "C:\Python36\lib\site-packages\itchat\components\login.py", line 240, in maintain_loop
    i = sync_check(self)
  File "C:\Python36\lib\site-packages\itchat\components\login.py", line 295, in sync_check
    r = self.s.get(url, params=params, headers=headers, timeout=config.TIMEOUT)
  File "C:\Python36\lib\site-packages\requests\sessions.py", line 515, in get
    return self.request('GET', url, **kwargs)
  File "C:\Python36\lib\site-packages\requests\sessions.py", line 502, in request
    resp = self.send(prep, **send_kwargs)
  File "C:\Python36\lib\site-packages\requests\sessions.py", line 612, in send
    r = adapter.send(request, **kwargs)
  File "C:\Python36\lib\site-packages\requests\adapters.py", line 504, in send
    raise ConnectionError(e, request=request)
requests.exceptions.ConnectionError: HTTPSConnectionPool(host='webpush.wx.qq.com', port=443): Max retries exceeded with url: /cgi-bin/mmwebwx-bin/synccheck?r=1499223281317&skey=%40crypt_1ad16c4_05d572229b40420fbbb1a28d4e90d16b&sid=utWLW%2BzfoVBfEKmS&uin=470536655&deviceid=e429345087967561&synckey=1_673300149%7C2_673300242%7C3_673300210%7C11_673300077%7C13_673270493%7C201_1499223159%7C1000_1499215980%7C1001_1499216252&_=1499223281317 (Caused by NewConnectionError('<urllib3.connection.VerifiedHTTPSConnection object at 0x02FF2770>: Failed to establish a new connection: [Errno 11004] getaddrinfo failed',))

INFO:itchat:LOG OUT!
INFO:itchat:Getting uuid of QR code.
INFO:itchat:Downloading QR code.
INFO:itchat:Please scan the QR code to log in.
INFO:itchat:Please press confirm on your phone.
INFO:itchat:Loading the contact, this may take a little while.
Caroline__PYQuanPin:Caroline
小威__PYQuanPin:xiaowei
阡陌🍃__PYQuanPin:qianmospanclassemojiemoji1f343span
张大帅__PYQuanPin:zhangdashuai
左涛瑞__PYQuanPin:zuotaorui
💯哈哈吴君志__PYQuanPin:?hahawujunzhi
吕春阳__PYQuanPin:lvchunyang
初见__PYQuanPin:chujian
奥普乐欢乐水世界__PYQuanPin:aopuyuehuanyueshuishijie
小胖__PYQuanPin:xiaopan
张创科老师13679260573__PYQuanPin:zhangchuangkelaoshi13679260573
人生在于拼搏__PYQuanPin:renshengzaiyupinbo
戴维__PYQuanPin:daiwei
Kerwin.徐__PYQuanPin:Kerwinxu
SUNNY__PYQuanPin:SUNNY
long__PYQuanPin:long
ONLY.love__PYQuanPin:ONLYlove
木子__PYQuanPin:muzi
Wong__PYQuanPin:Wong
携手声光舞美志远13080163331__PYQuanPin:xieshoushengguangwumeizhiyuan13080163331
乔布熙__PYQuanPin:qiaobuxi
fun__PYQuanPin:fun
A There won'r be you__PYQuanPin:ATherewonrbeyou
Mr.黑咖啡__PYQuanPin:Mrheigafei
哇塞天哪__PYQuanPin:wasaitianna
月亮__PYQuanPin:yueliang
你男朋友叫文杰么❇__PYQuanPin:ninanpengyoujiaowenjiemespanclassemojiemoji2747span
沛沛__PYQuanPin:peipei
路由__PYQuanPin:luyou
洋洋专业音响舞美__PYQuanPin:yangyangzhuanyeyinxiangwumei
影子传说__PYQuanPin:yingzichuanshui
无知__PYQuanPin:wuzhi
颖颖WANG__PYQuanPin:yingyingWANG
A.瀚雄金融服务__PYQuanPin:Ahanxiongjinrongfuwu
Panna__PYQuanPin:Panna
素颜最美__PYQuanPin:suyanzuimei
弓长__PYQuanPin:gongchang
小宇__PYQuanPin:xiaoyu
其实、等风来__PYQuanPin:qishidengfenglai
天之骄子__PYQuanPin:tianzhijiaozi
大海__PYQuanPin:dahai
爱吖、__PYQuanPin:aia
Adolph__PYQuanPin:Adolph
文林__PYQuanPin:wenlin
飞侠__PYQuanPin:feixia
马军胜__PYQuanPin:majunsheng
努比亚许昌解亚青__PYQuanPin:nubiyaxuchangxieyaqing
刘敏__PYQuanPin:liumin
功不唐捐__PYQuanPin:gongbutangjuan
知足常乐！红军__PYQuanPin:zhizuchangyuehongjun
云端漫步__PYQuanPin:yunduanmanbu
张勋__PYQuanPin:zhangxun
你好，亲爱的__PYQuanPin:nihaoqinaide
y帅__PYQuanPin:yshuai
吕阳阳__PYQuanPin:lvyangyang
Still me 。。。__PYQuanPin:Stillme
214℃™love__PYQuanPin:214spanclassemojiemoji2122spanlove
李凯龙__PYQuanPin:likailong
llj__PYQuanPin:llj
奔跑的小蜗牛__PYQuanPin:benpaodexiaowoniu
擱淺的往事__PYQuanPin:gejiandewangshi
陌陌__PYQuanPin:momo
郝廉龙__PYQuanPin:haolianlong
暗里着迷（郭洋15527277905）__PYQuanPin:anlizhaomiguoyang15527277905
老曹__PYQuanPin:laocao
洋洋__PYQuanPin:yangyang
POWER__PYQuanPin:POWER
啦啦啦__PYQuanPin:lalala
随心而遇__PYQuanPin:suixineryu
仰望星空(*^ω^*)__PYQuanPin:yangwangxingkong
旧时光__PYQuanPin:jiushiguang
依栘__PYQuanPin:yiyi
Holo__PYQuanPin:Holo
春辉__PYQuanPin:chunhui
A 李艳清__PYQuanPin:Aliyanqing
张玉魁18637417318__PYQuanPin:zhangyukui18637417318
强__PYQuanPin:qiang
十木__PYQuanPin:shimu
闫帅峰__PYQuanPin:yanshuaifeng
张培歌__PYQuanPin:zhangpeige
黄晓俊__PYQuanPin:huangxiaojun
马光__PYQuanPin:maguang
靳子帅__PYQuanPin:jinzishuai
杨高星__PYQuanPin:yanggaoxing
皮皮鲁__PYQuanPin:pipilu
黄果果爱的草莓派__PYQuanPin:huangguoguoaidecaomeipa
讯联☁️-Vivian__PYQuanPin:xunlianspanclassemojiemoji2601span?Vivian
浪花店小二__PYQuanPin:langhuadianxiaoer
张艺__PYQuanPin:zhangyi
淡墨__PYQuanPin:danmo
杨利卡17739777285__PYQuanPin:yanglika17739777285
我非英雄__PYQuanPin:wofeiyingxiong
张占胜__PYQuanPin:zhangzhansheng
青云__PYQuanPin:qingyun
༒Leon༒__PYQuanPin:?Leon?
殷清__PYQuanPin:yinqing
庄Sir__PYQuanPin:zhuangSir
闯先生__PYQuanPin:chuangxiansheng
莉莉__PYQuanPin:lili
演👮 员__PYQuanPin:yanspanclassemojiemoji1f46espanyuan
樊小铭🙃__PYQuanPin:fanxiaoming?
柯森__PYQuanPin:kesen
小解__PYQuanPin:xiaoxie
孙同学__PYQuanPin:suntongxue
小杰__PYQuanPin:xiaojie
INFO:itchat:Start auto replying.
INFO:itchat:LOG OUT!
INFO:itchat:Getting uuid of QR code.
INFO:itchat:Downloading QR code.
INFO:itchat:Please scan the QR code to log in.
INFO:itchat:Please press confirm on your phone.
INFO:itchat:Loading the contact, this may take a little while.
Caroline__PYQuanPin:Caroline
小威__PYQuanPin:xiaowei
阡陌🍃__PYQuanPin:qianmospanclassemojiemoji1f343span
张大帅__PYQuanPin:zhangdashuai
左涛瑞__PYQuanPin:zuotaorui
💯哈哈吴君志__PYQuanPin:?hahawujunzhi
吕春阳__PYQuanPin:lvchunyang
初见__PYQuanPin:chujian
奥普乐欢乐水世界__PYQuanPin:aopuyuehuanyueshuishijie
小胖__PYQuanPin:xiaopan
张创科老师13679260573__PYQuanPin:zhangchuangkelaoshi13679260573
人生在于拼搏__PYQuanPin:renshengzaiyupinbo
戴维__PYQuanPin:daiwei
Kerwin.徐__PYQuanPin:Kerwinxu
SUNNY__PYQuanPin:SUNNY
long__PYQuanPin:long
ONLY.love__PYQuanPin:ONLYlove
木子__PYQuanPin:muzi
Wong__PYQuanPin:Wong
携手声光舞美志远13080163331__PYQuanPin:xieshoushengguangwumeizhiyuan13080163331
乔布熙__PYQuanPin:qiaobuxi
fun__PYQuanPin:fun
A There won'r be you__PYQuanPin:ATherewonrbeyou
Mr.黑咖啡__PYQuanPin:Mrheigafei
哇塞天哪__PYQuanPin:wasaitianna
月亮__PYQuanPin:yueliang
你男朋友叫文杰么❇__PYQuanPin:ninanpengyoujiaowenjiemespanclassemojiemoji2747span
沛沛__PYQuanPin:peipei
路由__PYQuanPin:luyou
洋洋专业音响舞美__PYQuanPin:yangyangzhuanyeyinxiangwumei
影子传说__PYQuanPin:yingzichuanshui
无知__PYQuanPin:wuzhi
颖颖WANG__PYQuanPin:yingyingWANG
A.瀚雄金融服务__PYQuanPin:Ahanxiongjinrongfuwu
Panna__PYQuanPin:Panna
素颜最美__PYQuanPin:suyanzuimei
弓长__PYQuanPin:gongchang
小宇__PYQuanPin:xiaoyu
其实、等风来__PYQuanPin:qishidengfenglai
天之骄子__PYQuanPin:tianzhijiaozi
大海__PYQuanPin:dahai
爱吖、__PYQuanPin:aia
Adolph__PYQuanPin:Adolph
文林__PYQuanPin:wenlin
飞侠__PYQuanPin:feixia
马军胜__PYQuanPin:majunsheng
努比亚许昌解亚青__PYQuanPin:nubiyaxuchangxieyaqing
刘敏__PYQuanPin:liumin
功不唐捐__PYQuanPin:gongbutangjuan
知足常乐！红军__PYQuanPin:zhizuchangyuehongjun
云端漫步__PYQuanPin:yunduanmanbu
张勋__PYQuanPin:zhangxun
你好，亲爱的__PYQuanPin:nihaoqinaide
y帅__PYQuanPin:yshuai
吕阳阳__PYQuanPin:lvyangyang
Still me 。。。__PYQuanPin:Stillme
214℃™love__PYQuanPin:214spanclassemojiemoji2122spanlove
李凯龙__PYQuanPin:likailong
llj__PYQuanPin:llj
奔跑的小蜗牛__PYQuanPin:benpaodexiaowoniu
擱淺的往事__PYQuanPin:gejiandewangshi
陌陌__PYQuanPin:momo
郝廉龙__PYQuanPin:haolianlong
暗里着迷（郭洋15527277905）__PYQuanPin:anlizhaomiguoyang15527277905
老曹__PYQuanPin:laocao
洋洋__PYQuanPin:yangyang
POWER__PYQuanPin:POWER
啦啦啦__PYQuanPin:lalala
随心而遇__PYQuanPin:suixineryu
仰望星空(*^ω^*)__PYQuanPin:yangwangxingkong
旧时光__PYQuanPin:jiushiguang
依栘__PYQuanPin:yiyi
Holo__PYQuanPin:Holo
春辉__PYQuanPin:chunhui
A 李艳清__PYQuanPin:Aliyanqing
张玉魁18637417318__PYQuanPin:zhangyukui18637417318
强__PYQuanPin:qiang
十木__PYQuanPin:shimu
闫帅峰__PYQuanPin:yanshuaifeng
张培歌__PYQuanPin:zhangpeige
黄晓俊__PYQuanPin:huangxiaojun
马光__PYQuanPin:maguang
靳子帅__PYQuanPin:jinzishuai
杨高星__PYQuanPin:yanggaoxing
皮皮鲁__PYQuanPin:pipilu
黄果果爱的草莓派__PYQuanPin:huangguoguoaidecaomeipa
讯联☁️-Vivian__PYQuanPin:xunlianspanclassemojiemoji2601span?Vivian
浪花店小二__PYQuanPin:langhuadianxiaoer
张艺__PYQuanPin:zhangyi
淡墨__PYQuanPin:danmo
杨利卡17739777285__PYQuanPin:yanglika17739777285
我非英雄__PYQuanPin:wofeiyingxiong
张占胜__PYQuanPin:zhangzhansheng
青云__PYQuanPin:qingyun
༒Leon༒__PYQuanPin:?Leon?
殷清__PYQuanPin:yinqing
庄Sir__PYQuanPin:zhuangSir
闯先生__PYQuanPin:chuangxiansheng
莉莉__PYQuanPin:lili
演👮 员__PYQuanPin:yanspanclassemojiemoji1f46espanyuan
樊小铭🙃__PYQuanPin:fanxiaoming?
柯森__PYQuanPin:kesen
小解__PYQuanPin:xiaoxie
孙同学__PYQuanPin:suntongxue
小杰__PYQuanPin:xiaojie
INFO:itchat:Start auto replying.
INFO:itchat:LOG OUT!
INFO:itchat:Getting uuid of QR code.
INFO:itchat:Downloading QR code.
INFO:itchat:Please scan the QR code to log in.
INFO:itchat:Please press confirm on your phone.
INFO:itchat:Loading the contact, this may take a little while.
Caroline__PYQuanPin:Caroline
小威__PYQuanPin:xiaowei
阡陌🍃__PYQuanPin:qianmospanclassemojiemoji1f343span
张大帅__PYQuanPin:zhangdashuai
左涛瑞__PYQuanPin:zuotaorui
💯哈哈吴君志__PYQuanPin:?hahawujunzhi
吕春阳__PYQuanPin:lvchunyang
初见__PYQuanPin:chujian
奥普乐欢乐水世界__PYQuanPin:aopuyuehuanyueshuishijie
小胖__PYQuanPin:xiaopan
张创科老师13679260573__PYQuanPin:zhangchuangkelaoshi13679260573
人生在于拼搏__PYQuanPin:renshengzaiyupinbo
戴维__PYQuanPin:daiwei
Kerwin.徐__PYQuanPin:Kerwinxu
SUNNY__PYQuanPin:SUNNY
long__PYQuanPin:long
ONLY.love__PYQuanPin:ONLYlove
木子__PYQuanPin:muzi
Wong__PYQuanPin:Wong
携手声光舞美志远13080163331__PYQuanPin:xieshoushengguangwumeizhiyuan13080163331
乔布熙__PYQuanPin:qiaobuxi
fun__PYQuanPin:fun
A There won'r be you__PYQuanPin:ATherewonrbeyou
Mr.黑咖啡__PYQuanPin:Mrheigafei
哇塞天哪__PYQuanPin:wasaitianna
月亮__PYQuanPin:yueliang
你男朋友叫文杰么❇__PYQuanPin:ninanpengyoujiaowenjiemespanclassemojiemoji2747span
沛沛__PYQuanPin:peipei
路由__PYQuanPin:luyou
洋洋专业音响舞美__PYQuanPin:yangyangzhuanyeyinxiangwumei
影子传说__PYQuanPin:yingzichuanshui
无知__PYQuanPin:wuzhi
颖颖WANG__PYQuanPin:yingyingWANG
A.瀚雄金融服务__PYQuanPin:Ahanxiongjinrongfuwu
Panna__PYQuanPin:Panna
素颜最美__PYQuanPin:suyanzuimei
弓长__PYQuanPin:gongchang
小宇__PYQuanPin:xiaoyu
其实、等风来__PYQuanPin:qishidengfenglai
天之骄子__PYQuanPin:tianzhijiaozi
大海__PYQuanPin:dahai
爱吖、__PYQuanPin:aia
Adolph__PYQuanPin:Adolph
文林__PYQuanPin:wenlin
飞侠__PYQuanPin:feixia
马军胜__PYQuanPin:majunsheng
努比亚许昌解亚青__PYQuanPin:nubiyaxuchangxieyaqing
刘敏__PYQuanPin:liumin
功不唐捐__PYQuanPin:gongbutangjuan
知足常乐！红军__PYQuanPin:zhizuchangyuehongjun
云端漫步__PYQuanPin:yunduanmanbu
张勋__PYQuanPin:zhangxun
你好，亲爱的__PYQuanPin:nihaoqinaide
y帅__PYQuanPin:yshuai
吕阳阳__PYQuanPin:lvyangyang
Still me 。。。__PYQuanPin:Stillme
214℃™love__PYQuanPin:214spanclassemojiemoji2122spanlove
李凯龙__PYQuanPin:likailong
llj__PYQuanPin:llj
奔跑的小蜗牛__PYQuanPin:benpaodexiaowoniu
擱淺的往事__PYQuanPin:gejiandewangshi
陌陌__PYQuanPin:momo
郝廉龙__PYQuanPin:haolianlong
暗里着迷（郭洋15527277905）__PYQuanPin:anlizhaomiguoyang15527277905
老曹__PYQuanPin:laocao
洋洋__PYQuanPin:yangyang
POWER__PYQuanPin:POWER
啦啦啦__PYQuanPin:lalala
随心而遇__PYQuanPin:suixineryu
仰望星空(*^ω^*)__PYQuanPin:yangwangxingkong
旧时光__PYQuanPin:jiushiguang
依栘__PYQuanPin:yiyi
Holo__PYQuanPin:Holo
春辉__PYQuanPin:chunhui
A 李艳清__PYQuanPin:Aliyanqing
张玉魁18637417318__PYQuanPin:zhangyukui18637417318
强__PYQuanPin:qiang
十木__PYQuanPin:shimu
闫帅峰__PYQuanPin:yanshuaifeng
张培歌__PYQuanPin:zhangpeige
黄晓俊__PYQuanPin:huangxiaojun
马光__PYQuanPin:maguang
靳子帅__PYQuanPin:jinzishuai
杨高星__PYQuanPin:yanggaoxing
皮皮鲁__PYQuanPin:pipilu
黄果果爱的草莓派__PYQuanPin:huangguoguoaidecaomeipa
讯联☁️-Vivian__PYQuanPin:xunlianspanclassemojiemoji2601span?Vivian
浪花店小二__PYQuanPin:langhuadianxiaoer
张艺__PYQuanPin:zhangyi
淡墨__PYQuanPin:danmo
杨利卡17739777285__PYQuanPin:yanglika17739777285
我非英雄__PYQuanPin:wofeiyingxiong
张占胜__PYQuanPin:zhangzhansheng
青云__PYQuanPin:qingyun
༒Leon༒__PYQuanPin:?Leon?
殷清__PYQuanPin:yinqing
庄Sir__PYQuanPin:zhuangSir
闯先生__PYQuanPin:chuangxiansheng
莉莉__PYQuanPin:lili
演👮 员__PYQuanPin:yanspanclassemojiemoji1f46espanyuan
樊小铭🙃__PYQuanPin:fanxiaoming?
柯森__PYQuanPin:kesen
小解__PYQuanPin:xiaoxie
孙同学__PYQuanPin:suntongxue
小杰__PYQuanPin:xiaojie
INFO:itchat:Start auto replying.
INFO:itchat:LOG OUT!
INFO:itchat:Getting uuid of QR code.
INFO:itchat:Downloading QR code.
INFO:itchat:Please scan the QR code to log in.
INFO:itchat:Please press confirm on your phone.
INFO:itchat:Loading the contact, this may take a little while.
张松松__PYQuanPin:
Caroline__PYQuanPin:Caroline
INFO:itchat:Start auto replying.
INFO:itchat:Getting uuid of QR code.
INFO:itchat:Downloading QR code.
INFO:itchat:Please scan the QR code to log in.
INFO:itchat:Please press confirm on your phone.
INFO:itchat:Loading the contact, this may take a little while.
Caroline__PYQuanPin:Caroline
小威__PYQuanPin:xiaowei
阡陌🍃__PYQuanPin:qianmospanclassemojiemoji1f343span
张大帅__PYQuanPin:zhangdashuai
左涛瑞__PYQuanPin:zuotaorui
💯哈哈吴君志__PYQuanPin:?hahawujunzhi
吕春阳__PYQuanPin:lvchunyang
初见__PYQuanPin:chujian
奥普乐欢乐水世界__PYQuanPin:aopuyuehuanyueshuishijie
小胖__PYQuanPin:xiaopan
张创科老师13679260573__PYQuanPin:zhangchuangkelaoshi13679260573
人生在于拼搏__PYQuanPin:renshengzaiyupinbo
戴维__PYQuanPin:daiwei
Kerwin.徐__PYQuanPin:Kerwinxu
SUNNY__PYQuanPin:SUNNY
long__PYQuanPin:long
ONLY.love__PYQuanPin:ONLYlove
木子__PYQuanPin:muzi
Wong__PYQuanPin:Wong
携手声光舞美志远13080163331__PYQuanPin:xieshoushengguangwumeizhiyuan13080163331
乔布熙__PYQuanPin:qiaobuxi
fun__PYQuanPin:fun
A There won'r be you__PYQuanPin:ATherewonrbeyou
Mr.黑咖啡__PYQuanPin:Mrheigafei
哇塞天哪__PYQuanPin:wasaitianna
月亮__PYQuanPin:yueliang
你男朋友叫文杰么❇__PYQuanPin:ninanpengyoujiaowenjiemespanclassemojiemoji2747span
沛沛__PYQuanPin:peipei
路由__PYQuanPin:luyou
洋洋专业音响舞美__PYQuanPin:yangyangzhuanyeyinxiangwumei
影子传说__PYQuanPin:yingzichuanshui
无知__PYQuanPin:wuzhi
颖颖WANG__PYQuanPin:yingyingWANG
A.瀚雄金融服务__PYQuanPin:Ahanxiongjinrongfuwu
Panna__PYQuanPin:Panna
素颜最美__PYQuanPin:suyanzuimei
弓长__PYQuanPin:gongchang
小宇__PYQuanPin:xiaoyu
其实、等风来__PYQuanPin:qishidengfenglai
天之骄子__PYQuanPin:tianzhijiaozi
大海__PYQuanPin:dahai
爱吖、__PYQuanPin:aia
Adolph__PYQuanPin:Adolph
文林__PYQuanPin:wenlin
飞侠__PYQuanPin:feixia
马军胜__PYQuanPin:majunsheng
努比亚许昌解亚青__PYQuanPin:nubiyaxuchangxieyaqing
刘敏__PYQuanPin:liumin
功不唐捐__PYQuanPin:gongbutangjuan
知足常乐！红军__PYQuanPin:zhizuchangyuehongjun
云端漫步__PYQuanPin:yunduanmanbu
张勋__PYQuanPin:zhangxun
你好，亲爱的__PYQuanPin:nihaoqinaide
y帅__PYQuanPin:yshuai
吕阳阳__PYQuanPin:lvyangyang
Still me 。。。__PYQuanPin:Stillme
214℃™love__PYQuanPin:214spanclassemojiemoji2122spanlove
李凯龙__PYQuanPin:likailong
llj__PYQuanPin:llj
奔跑的小蜗牛__PYQuanPin:benpaodexiaowoniu
擱淺的往事__PYQuanPin:gejiandewangshi
陌陌__PYQuanPin:momo
郝廉龙__PYQuanPin:haolianlong
暗里着迷（郭洋15527277905）__PYQuanPin:anlizhaomiguoyang15527277905
老曹__PYQuanPin:laocao
洋洋__PYQuanPin:yangyang
POWER__PYQuanPin:POWER
啦啦啦__PYQuanPin:lalala
随心而遇__PYQuanPin:suixineryu
仰望星空(*^ω^*)__PYQuanPin:yangwangxingkong
旧时光__PYQuanPin:jiushiguang
依栘__PYQuanPin:yiyi
Holo__PYQuanPin:Holo
春辉__PYQuanPin:chunhui
A 李艳清__PYQuanPin:Aliyanqing
张玉魁18637417318__PYQuanPin:zhangyukui18637417318
强__PYQuanPin:qiang
十木__PYQuanPin:shimu
闫帅峰__PYQuanPin:yanshuaifeng
张培歌__PYQuanPin:zhangpeige
黄晓俊__PYQuanPin:huangxiaojun
马光__PYQuanPin:maguang
靳子帅__PYQuanPin:jinzishuai
杨高星__PYQuanPin:yanggaoxing
皮皮鲁__PYQuanPin:pipilu
黄果果爱的草莓派__PYQuanPin:huangguoguoaidecaomeipa
讯联☁️-Vivian__PYQuanPin:xunlianspanclassemojiemoji2601span?Vivian
浪花店小二__PYQuanPin:langhuadianxiaoer
张艺__PYQuanPin:zhangyi
淡墨__PYQuanPin:danmo
杨利卡17739777285__PYQuanPin:yanglika17739777285
我非英雄__PYQuanPin:wofeiyingxiong
张占胜__PYQuanPin:zhangzhansheng
青云__PYQuanPin:qingyun
༒Leon༒__PYQuanPin:?Leon?
殷清__PYQuanPin:yinqing
庄Sir__PYQuanPin:zhuangSir
闯先生__PYQuanPin:chuangxiansheng
莉莉__PYQuanPin:lili
演👮 员__PYQuanPin:yanspanclassemojiemoji1f46espanyuan
樊小铭🙃__PYQuanPin:fanxiaoming?
柯森__PYQuanPin:kesen
小解__PYQuanPin:xiaoxie
佛前一粒尘__PYQuanPin:foqianyilichen
孙同学__PYQuanPin:suntongxue
INFO:itchat:Start auto replying.
WARNING:itchat:Traceback (most recent call last):
  File "C:\Python36\lib\site-packages\itchat\components\register.py", line 60, in configured_reply
    r = replyFn(msg)
  File "weixin.py", line 20, in text_reply
    if autoUserNames.has_key(msg['FromUserName']):
AttributeError: 'dict' object has no attribute 'has_key'

INFO:itchat:Bye~
